Workbook

Sheet Overview
A1: Category | B1: All Tasks | C1: To Improve | D1: Done | E1: %
A2: Technical Foundation | B2: 14 | C2: =COUNTIFS('Technical Foundation'!D:D,"Bad")+COUNTIFS('Technical Foundation'!D:D,"Can be Improved") | D2: =COUNTIFS('Technical Foundation'!A:A,TRUE) | E2: =IF(B2>0,D2/B2,0)
A3: Content Optimization | B3: 18 | C3: =COUNTIFS('Content Optimization'!D:D,"Bad")+COUNTIFS('Content Optimization'!D:D,"Can be Improved") | D3: =COUNTIFS('Content Optimization'!A:A,TRUE) | E3: =IF(B3>0,D3/B3,0)
A4: Trust and Authority | B4: 15 | C4: =COUNTIFS('Trust and Authority'!D:D,"Bad")+COUNTIFS('Trust and Authority'!D:D,"Can be Improved") | D4: =COUNTIFS('Trust and Authority'!A:A,TRUE) | E4: =IF(B4>0,D4/B4,0)
A5: LLM-Specific Optimization | B5: 18 | C5: =COUNTIFS('LLM-Specific Optimization'!D:D,"Bad")+COUNTIFS('LLM-Specific Optimization'!D:D,"Can be Improved") | D5: =COUNTIFS('LLM-Specific Optimization'!A:A,TRUE) | E5: =IF(B5>0,D5/B5,0)
A6: Monitoring and Analytics | B6: 12 | C6: =COUNTIFS('Monitoring and Analytics'!D:D,"Bad")+COUNTIFS('Monitoring and Analytics'!D:D,"Can be Improved") | D6: =COUNTIFS('Monitoring and Analytics'!A:A,TRUE) | E6: =IF(B6>0,D6/B6,0)
A7: Content Strategy | B7: 12 | C7: =COUNTIFS('Content Strategy'!D:D,"Bad")+COUNTIFS('Content Strategy'!D:D,"Can be Improved") | D7: =COUNTIFS('Content Strategy'!A:A,TRUE) | E7: =IF(B7>0,D7/B7,0)
A8: Competitive Intelligence | B8: 10 | C8: =COUNTIFS('Competitive Intelligence'!D:D,"Bad")+COUNTIFS('Competitive Intelligence'!D:D,"Can be Improved") | D8: =COUNTIFS('Competitive Intelligence'!A:A,TRUE) | E8: =IF(B8>0,D8/B8,0)

Sheet Technical Foundation
B1: Technical Foundation - AEO Checkpoint | C1: Example | D1: Evaluation | E1: Factor | F1: Impact | G1: Impact | H1: Cost | I1: Cost | J1: Cost for Sum | K1: Sum | L1: Max | M1: Priority
B2: Technical Foundation
A3: FALSE | B3: robots.txt allows AI crawlers (GPTBot, OAI-SearchBot, ChatGPT-User, ClaudeBot, PerplexityBot, Applebot, Bytespider) | C3: User-agent: GPTBot / Allow: / | E3: =IF(D3="Not Relevant","",IF(D3="Good","",IF(D3="Bad",1.33,1))) | G3: =IFERROR(SPARKLINE(F3,{"charttype","bar";"max",3;"min",1;"color1",IF(F3=3,"#4078DD",IF(F3=2,"#9CB7E9","#CED9EF"))}),"") | I3: =IFERROR(SPARKLINE(H3,{"charttype","bar";"max",3;"min",1;"color1",IF(H3=3,"#4078DD",IF(H3=2,"#9CB7E9","#CED9EF"))}),"") | J3: =IF(H3=1,3,IF(H3=2,2,1)) | K3: =ROUNDUP(((J3+F3)*E3),1) | L3: 8 | M3: =IFERROR(IF(A3=FALSE,SPARKLINE(K3:L3,{"charttype","bar";"max",8;"min",0;"color1",IF(K3>=5,"green",IF(K3<=3,"orange","#C9C21D"));"color2","#eeeeee"}),"Done"),"")
A4: FALSE | B4: Critical pages server-side rendered (SSR) | C4: Homepage and pricing render full HTML without JavaScript | E4: =IF(D4="Not Relevant","",IF(D4="Good","",IF(D4="Bad",1.33,1))) | G4: =IFERROR(SPARKLINE(F4,{"charttype","bar";"max",3;"min",1;"color1",IF(F4=3,"#4078DD",IF(F4=2,"#9CB7E9","#CED9EF"))}),"") | I4: =IFERROR(SPARKLINE(H4,{"charttype","bar";"max",3;"min",1;"color1",IF(H4=3,"#4078DD",IF(H4=2,"#9CB7E9","#CED9EF"))}),"") | J4: =IF(H4=1,3,IF(H4=2,2,1)) | K4: =ROUNDUP(((J4+F4)*E4),1) | L4: 8 | M4: =IFERROR(IF(A4=FALSE,SPARKLINE(K4:L4,{"charttype","bar";"max",8;"min",0;"color1",IF(K4>=5,"green",IF(K4<=3,"orange","#C9C21D"));"color2","#eeeeee"}),"Done"),"")
A5: FALSE | B5: Page load under 3 seconds | C5: Test via PageSpeed Insights or WebPageTest | E5: =IF(D5="Not Relevant","",IF(D5="Good","",IF(D5="Bad",1.33,1))) | G5: =IFERROR(SPARKLINE(F5,{"charttype","bar";"max",3;"min",1;"color1",IF(F5=3,"#4078DD",IF(F5=2,"#9CB7E9","#CED9EF"))}),"") | I5: =IFERROR(SPARKLINE(H5,{"charttype","bar";"max",3;"min",1;"color1",IF(H5=3,"#4078DD",IF(H5=2,"#9CB7E9","#CED9EF"))}),"") | J5: =IF(H5=1,3,IF(H5=2,2,1)) | K5: =ROUNDUP(((J5+F5)*E5),1) | L5: 8 | M5: =IFERROR(IF(A5=FALSE,SPARKLINE(K5:L5,{"charttype","bar";"max",8;"min",0;"color1",IF(K5>=5,"green",IF(K5<=3,"orange","#C9C21D"));"color2","#eeeeee"}),"Done"),"")
A6: FALSE | B6: Schema.org markup on key pages (Organization, Product, FAQ, HowTo, SameAs) | C6: @type: Organization with sameAs linking to LinkedIn, Crunchbase, G2 | E6: =IF(D6="Not Relevant","",IF(D6="Good","",IF(D6="Bad",1.33,1))) | G6: =IFERROR(SPARKLINE(F6,{"charttype","bar";"max",3;"min",1;"color1",IF(F6=3,"#4078DD",IF(F6=2,"#9CB7E9","#CED9EF"))}),"") | I6: =IFERROR(SPARKLINE(H6,{"charttype","bar";"max",3;"min",1;"color1",IF(H6=3,"#4078DD",IF(H6=2,"#9CB7E9","#CED9EF"))}),"") | J6: =IF(H6=1,3,IF(H6=2,2,1)) | K6: =ROUNDUP(((J6+F6)*E6),1) | L6: 8 | M6: =IFERROR(IF(A6=FALSE,SPARKLINE(K6:L6,{"charttype","bar";"max",8;"min",0;"color1",IF(K6>=5,"green",IF(K6<=3,"orange","#C9C21D"));"color2","#eeeeee"}),"Done"),"")
A7: FALSE | B7: Sitemap.xml submitted to Google Search Console and Bing Webmaster Tools | C7: sitemap.xml includes all indexable pages with lastmod dates | E7: =IF(D7="Not Relevant","",IF(D7="Good","",IF(D7="Bad",1.33,1))) | G7: =IFERROR(SPARKLINE(F7,{"charttype","bar";"max",3;"min",1;"color1",IF(F7=3,"#4078DD",IF(F7=2,"#9CB7E9","#CED9EF"))}),"") | I7: =IFERROR(SPARKLINE(H7,{"charttype","bar";"max",3;"min",1;"color1",IF(H7=3,"#4078DD",IF(H7=2,"#9CB7E9","#CED9EF"))}),"") | J7: =IF(H7=1,3,IF(H7=2,2,1)) | K7: =ROUNDUP(((J7+F7)*E7),1) | L7: 8 | M7: =IFERROR(IF(A7=FALSE,SPARKLINE(K7:L7,{"charttype","bar";"max",8;"min",0;"color1",IF(K7>=5,"green",IF(K7<=3,"orange","#C9C21D"));"color2","#eeeeee"}),"Done"),"")
A8: FALSE | B8: HTML tables on key pages for Gemini grounding | C8: <table> with pricing tiers, feature comparisons, stats | E8: =IF(D8="Not Relevant","",IF(D8="Good","",IF(D8="Bad",1.33,1))) | G8: =IFERROR(SPARKLINE(F8,{"charttype","bar";"max",3;"min",1;"color1",IF(F8=3,"#4078DD",IF(F8=2,"#9CB7E9","#CED9EF"))}),"") | I8: =IFERROR(SPARKLINE(H8,{"charttype","bar";"max",3;"min",1;"color1",IF(H8=3,"#4078DD",IF(H8=2,"#9CB7E9","#CED9EF"))}),"") | J8: =IF(H8=1,3,IF(H8=2,2,1)) | K8: =ROUNDUP(((J8+F8)*E8),1) | L8: 8 | M8: =IFERROR(IF(A8=FALSE,SPARKLINE(K8:L8,{"charttype","bar";"max",8;"min",0;"color1",IF(K8>=5,"green",IF(K8<=3,"orange","#C9C21D"));"color2","#eeeeee"}),"Done"),"")
A9: FALSE | B9: HTTPS everywhere | C9: All pages load via https:// with no mixed content warnings | E9: =IF(D9="Not Relevant","",IF(D9="Good","",IF(D9="Bad",1.33,1))) | G9: =IFERROR(SPARKLINE(F9,{"charttype","bar";"max",3;"min",1;"color1",IF(F9=3,"#4078DD",IF(F9=2,"#9CB7E9","#CED9EF"))}),"") | I9: =IFERROR(SPARKLINE(H9,{"charttype","bar";"max",3;"min",1;"color1",IF(H9=3,"#4078DD",IF(H9=2,"#9CB7E9","#CED9EF"))}),"") | J9: =IF(H9=1,3,IF(H9=2,2,1)) | K9: =ROUNDUP(((J9+F9)*E9),1) | L9: 8 | M9: =IFERROR(IF(A9=FALSE,SPARKLINE(K9:L9,{"charttype","bar";"max",8;"min",0;"color1",IF(K9>=5,"green",IF(K9<=3,"orange","#C9C21D"));"color2","#eeeeee"}),"Done"),"")
A10: FALSE | B10: Clean URL structure | C10: /features/reporting not /page?id=47&cat=3 | E10: =IF(D10="Not Relevant","",IF(D10="Good","",IF(D10="Bad",1.33,1))) | G10: =IFERROR(SPARKLINE(F10,{"charttype","bar";"max",3;"min",1;"color1",IF(F10=3,"#4078DD",IF(F10=2,"#9CB7E9","#CED9EF"))}),"") | I10: =IFERROR(SPARKLINE(H10,{"charttype","bar";"max",3;"min",1;"color1",IF(H10=3,"#4078DD",IF(H10=2,"#9CB7E9","#CED9EF"))}),"") | J10: =IF(H10=1,3,IF(H10=2,2,1)) | K10: =ROUNDUP(((J10+F10)*E10),1) | L10: 8 | M10: =IFERROR(IF(A10=FALSE,SPARKLINE(K10:L10,{"charttype","bar";"max",8;"min",0;"color1",IF(K10>=5,"green",IF(K10<=3,"orange","#C9C21D"));"color2","#eeeeee"}),"Done"),"")
A11: FALSE | B11: Canonical tags configured on all pages | C11: link rel="canonical" href="..." on every page | E11: =IF(D11="Not Relevant","",IF(D11="Good","",IF(D11="Bad",1.33,1))) | G11: =IFERROR(SPARKLINE(F11,{"charttype","bar";"max",3;"min",1;"color1",IF(F11=3,"#4078DD",IF(F11=2,"#9CB7E9","#CED9EF"))}),"") | I11: =IFERROR(SPARKLINE(H11,{"charttype","bar";"max",3;"min",1;"color1",IF(H11=3,"#4078DD",IF(H11=2,"#9CB7E9","#CED9EF"))}),"") | J11: =IF(H11=1,3,IF(H11=2,2,1)) | K11: =ROUNDUP(((J11+F11)*E11),1) | L11: 8 | M11: =IFERROR(IF(A11=FALSE,SPARKLINE(K11:L11,{"charttype","bar";"max",8;"min",0;"color1",IF(K11>=5,"green",IF(K11<=3,"orange","#C9C21D"));"color2","#eeeeee"}),"Done"),"")
A12: FALSE | B12: llms.txt file created at site root | C12: /llms.txt with brand summary, key facts, and structured data pointers | E12: =IF(D12="Not Relevant","",IF(D12="Good","",IF(D12="Bad",1.33,1))) | G12: =IFERROR(SPARKLINE(F12,{"charttype","bar";"max",3;"min",1;"color1",IF(F12=3,"#4078DD",IF(F12=2,"#9CB7E9","#CED9EF"))}),"") | I12: =IFERROR(SPARKLINE(H12,{"charttype","bar";"max",3;"min",1;"color1",IF(H12=3,"#4078DD",IF(H12=2,"#9CB7E9","#CED9EF"))}),"") | J12: =IF(H12=1,3,IF(H12=2,2,1)) | K12: =ROUNDUP(((J12+F12)*E12),1) | L12: 8 | M12: =IFERROR(IF(A12=FALSE,SPARKLINE(K12:L12,{"charttype","bar";"max",8;"min",0;"color1",IF(K12>=5,"green",IF(K12<=3,"orange","#C9C21D"));"color2","#eeeeee"}),"Done"),"")
A13: FALSE | B13: No critical content hidden behind JS tabs or accordions | C13: Pricing and features visible in page source without JS execution | E13: =IF(D13="Not Relevant","",IF(D13="Good","",IF(D13="Bad",1.33,1))) | G13: =IFERROR(SPARKLINE(F13,{"charttype","bar";"max",3;"min",1;"color1",IF(F13=3,"#4078DD",IF(F13=2,"#9CB7E9","#CED9EF"))}),"") | I13: =IFERROR(SPARKLINE(H13,{"charttype","bar";"max",3;"min",1;"color1",IF(H13=3,"#4078DD",IF(H13=2,"#9CB7E9","#CED9EF"))}),"") | J13: =IF(H13=1,3,IF(H13=2,2,1)) | K13: =ROUNDUP(((J13+F13)*E13),1) | L13: 8 | M13: =IFERROR(IF(A13=FALSE,SPARKLINE(K13:L13,{"charttype","bar";"max",8;"min",0;"color1",IF(K13>=5,"green",IF(K13<=3,"orange","#C9C21D"));"color2","#eeeeee"}),"Done"),"")
A14: FALSE | B14: Mobile rendering verified for AI crawlers | C14: Test with mobile user-agent; ensure same content as desktop | E14: =IF(D14="Not Relevant","",IF(D14="Good","",IF(D14="Bad",1.33,1))) | G14: =IFERROR(SPARKLINE(F14,{"charttype","bar";"max",3;"min",1;"color1",IF(F14=3,"#4078DD",IF(F14=2,"#9CB7E9","#CED9EF"))}),"") | I14: =IFERROR(SPARKLINE(H14,{"charttype","bar";"max",3;"min",1;"color1",IF(H14=3,"#4078DD",IF(H14=2,"#9CB7E9","#CED9EF"))}),"") | J14: =IF(H14=1,3,IF(H14=2,2,1)) | K14: =ROUNDUP(((J14+F14)*E14),1) | L14: 8 | M14: =IFERROR(IF(A14=FALSE,SPARKLINE(K14:L14,{"charttype","bar";"max",8;"min",0;"color1",IF(K14>=5,"green",IF(K14<=3,"orange","#C9C21D"));"color2","#eeeeee"}),"Done"),"")
... A16: FALSE | B16: Cache-busting parameters ready for content updates | C16: ?v=2024-01 appended to URLs after major content changes | E16: =IF(D16="Not Relevant","",IF(D16="Good","",IF(D16="Bad",1.33,1))) | G16: =IFERROR(SPARKLINE(F16,{"charttype","bar";"max",3;"min",1;"color1",IF(F16=3,"#4078DD",IF(F16=2,"#9CB7E9","#CED9EF"))}),"") | I16: =IFERROR(SPARKLINE(H16,{"charttype","bar";"max",3;"min",1;"color1",IF(H16=3,"#4078DD",IF(H16=2,"#9CB7E9","#CED9EF"))}),"") | J16: =IF(H16=1,3,IF(H16=2,2,1)) | K16: =ROUNDUP(((J16+F16)*E16),1) | L16: 8 | M16: =IFERROR(IF(A16=FALSE,SPARKLINE(K16:L16,{"charttype","bar";"max",8;"min",0;"color1",IF(K16>=5,"green",IF(K16<=3,"orange","#C9C21D"));"color2","#eeeeee"}),"Done"),"")

Sheet Content Optimization
B1: Content Optimization - AEO Checkpoint | C1: Example | D1: Evaluation | E1: Factor | F1: Impact | G1: Impact | H1: Cost | I1: Cost | J1: Cost for Sum | K1: Sum | L1: Max | M1: Priority
B2: Content Optimization
A3: FALSE | B3: First 50 words state WHO / WHAT / WHERE / PRICE | C3: Acme is a B2B sales platform based in London. Plans start at $49/mo. | E3: =IF(D3="Not Relevant","",IF(D3="Good","",IF(D3="Bad",1.33,1))) | G3: =IFERROR(SPARKLINE(F3,{"charttype","bar";"max",3;"min",1;"color1",IF(F3=3,"#4078DD",IF(F3=2,"#9CB7E9","#CED9EF"))}),"") | I3: =IFERROR(SPARKLINE(H3,{"charttype","bar";"max",3;"min",1;"color1",IF(H3=3,"#4078DD",IF(H3=2,"#9CB7E9","#CED9EF"))}),"") | J3: =IF(H3=1,3,IF(H3=2,2,1)) | K3: =ROUNDUP(((J3+F3)*E3),1) | L3: 8 | M3: =IFERROR(IF(A3=FALSE,SPARKLINE(K3:L3,{"charttype","bar";"max",8;"min",0;"color1",IF(K3>=5,"green",IF(K3<=3,"orange","#C9C21D"));"color2","#eeeeee"}),"Done"),"")
A4: FALSE | B4: No rhetorical questions as page openers | C4: Bad: "Ready to transform?" Good: "Acme automates invoice processing." | E4: =IF(D4="Not Relevant","",IF(D4="Good","",IF(D4="Bad",1.33,1))) | G4: =IFERROR(SPARKLINE(F4,{"charttype","bar";"max",3;"min",1;"color1",IF(F4=3,"#4078DD",IF(F4=2,"#9CB7E9","#CED9EF"))}),"") | I4: =IFERROR(SPARKLINE(H4,{"charttype","bar";"max",3;"min",1;"color1",IF(H4=3,"#4078DD",IF(H4=2,"#9CB7E9","#CED9EF"))}),"") | J4: =IF(H4=1,3,IF(H4=2,2,1)) | K4: =ROUNDUP(((J4+F4)*E4),1) | L4: 8 | M4: =IFERROR(IF(A4=FALSE,SPARKLINE(K4:L4,{"charttype","bar";"max",8;"min",0;"color1",IF(K4>=5,"green",IF(K4<=3,"orange","#C9C21D"));"color2","#eeeeee"}),"Done"),"")
A5: FALSE | B5: No vague promises in opening copy | C5: Bad: "Unlock your potential" Good: "Reduce churn by 23%" | E5: =IF(D5="Not Relevant","",IF(D5="Good","",IF(D5="Bad",1.33,1))) | G5: =IFERROR(SPARKLINE(F5,{"charttype","bar";"max",3;"min",1;"color1",IF(F5=3,"#4078DD",IF(F5=2,"#9CB7E9","#CED9EF"))}),"") | I5: =IFERROR(SPARKLINE(H5,{"charttype","bar";"max",3;"min",1;"color1",IF(H5=3,"#4078DD",IF(H5=2,"#9CB7E9","#CED9EF"))}),"") | J5: =IF(H5=1,3,IF(H5=2,2,1)) | K5: =ROUNDUP(((J5+F5)*E5),1) | L5: 8 | M5: =IFERROR(IF(A5=FALSE,SPARKLINE(K5:L5,{"charttype","bar";"max",8;"min",0;"color1",IF(K5>=5,"green",IF(K5<=3,"orange","#C9C21D"));"color2","#eeeeee"}),"Done"),"")
A6: FALSE | B6: TL;DR or Key Takeaways at top of long-form pages | C6: TL;DR: Acme processes 10M invoices/year for 2,400 businesses at $49-199/mo | E6: =IF(D6="Not Relevant","",IF(D6="Good","",IF(D6="Bad",1.33,1))) | G6: =IFERROR(SPARKLINE(F6,{"charttype","bar";"max",3;"min",1;"color1",IF(F6=3,"#4078DD",IF(F6=2,"#9CB7E9","#CED9EF"))}),"") | I6: =IFERROR(SPARKLINE(H6,{"charttype","bar";"max",3;"min",1;"color1",IF(H6=3,"#4078DD",IF(H6=2,"#9CB7E9","#CED9EF"))}),"") | J6: =IF(H6=1,3,IF(H6=2,2,1)) | K6: =ROUNDUP(((J6+F6)*E6),1) | L6: 8 | M6: =IFERROR(IF(A6=FALSE,SPARKLINE(K6:L6,{"charttype","bar";"max",8;"min",0;"color1",IF(K6>=5,"green",IF(K6<=3,"orange","#C9C21D"));"color2","#eeeeee"}),"Done"),"")
A7: FALSE | B7: Pricing hard-coded in HTML text (not behind Contact Us) | C7: Plans: Starter $49/mo, Pro $99/mo, Enterprise $299/mo | E7: =IF(D7="Not Relevant","",IF(D7="Good","",IF(D7="Bad",1.33,1))) | G7: =IFERROR(SPARKLINE(F7,{"charttype","bar";"max",3;"min",1;"color1",IF(F7=3,"#4078DD",IF(F7=2,"#9CB7E9","#CED9EF"))}),"") | I7: =IFERROR(SPARKLINE(H7,{"charttype","bar";"max",3;"min",1;"color1",IF(H7=3,"#4078DD",IF(H7=2,"#9CB7E9","#CED9EF"))}),"") | J7: =IF(H7=1,3,IF(H7=2,2,1)) | K7: =ROUNDUP(((J7+F7)*E7),1) | L7: 8 | M7: =IFERROR(IF(A7=FALSE,SPARKLINE(K7:L7,{"charttype","bar";"max",8;"min",0;"color1",IF(K7>=5,"green",IF(K7<=3,"orange","#C9C21D"));"color2","#eeeeee"}),"Done"),"")
A8: FALSE | B8: Specific numbers replace vague claims | C8: 2,400+ businesses not "Trusted by thousands" | E8: =IF(D8="Not Relevant","",IF(D8="Good","",IF(D8="Bad",1.33,1))) | G8: =IFERROR(SPARKLINE(F8,{"charttype","bar";"max",3;"min",1;"color1",IF(F8=3,"#4078DD",IF(F8=2,"#9CB7E9","#CED9EF"))}),"") | I8: =IFERROR(SPARKLINE(H8,{"charttype","bar";"max",3;"min",1;"color1",IF(H8=3,"#4078DD",IF(H8=2,"#9CB7E9","#CED9EF"))}),"") | J8: =IF(H8=1,3,IF(H8=2,2,1)) | K8: =ROUNDUP(((J8+F8)*E8),1) | L8: 8 | M8: =IFERROR(IF(A8=FALSE,SPARKLINE(K8:L8,{"charttype","bar";"max",8;"min",0;"color1",IF(K8>=5,"green",IF(K8<=3,"orange","#C9C21D"));"color2","#eeeeee"}),"Done"),"")
A9: FALSE | B9: HTML tables for structured data (not images or PDFs) | C9: <table> for pricing, feature comparisons, specs | E9: =IF(D9="Not Relevant","",IF(D9="Good","",IF(D9="Bad",1.33,1))) | G9: =IFERROR(SPARKLINE(F9,{"charttype","bar";"max",3;"min",1;"color1",IF(F9=3,"#4078DD",IF(F9=2,"#9CB7E9","#CED9EF"))}),"") | I9: =IFERROR(SPARKLINE(H9,{"charttype","bar";"max",3;"min",1;"color1",IF(H9=3,"#4078DD",IF(H9=2,"#9CB7E9","#CED9EF"))}),"") | J9: =IF(H9=1,3,IF(H9=2,2,1)) | K9: =ROUNDUP(((J9+F9)*E9),1) | L9: 8 | M9: =IFERROR(IF(A9=FALSE,SPARKLINE(K9:L9,{"charttype","bar";"max",8;"min",0;"color1",IF(K9>=5,"green",IF(K9<=3,"orange","#C9C21D"));"color2","#eeeeee"}),"Done"),"")
A10: FALSE | B10: FAQ section on every key page in Q&A format | C10: How much does Acme cost? Plans start at $49/mo... | E10: =IF(D10="Not Relevant","",IF(D10="Good","",IF(D10="Bad",1.33,1))) | G10: =IFERROR(SPARKLINE(F10,{"charttype","bar";"max",3;"min",1;"color1",IF(F10=3,"#4078DD",IF(F10=2,"#9CB7E9","#CED9EF"))}),"") | I10: =IFERROR(SPARKLINE(H10,{"charttype","bar";"max",3;"min",1;"color1",IF(H10=3,"#4078DD",IF(H10=2,"#9CB7E9","#CED9EF"))}),"") | J10: =IF(H10=1,3,IF(H10=2,2,1)) | K10: =ROUNDUP(((J10+F10)*E10),1) | L10: 8 | M10: =IFERROR(IF(A10=FALSE,SPARKLINE(K10:L10,{"charttype","bar";"max",8;"min",0;"color1",IF(K10>=5,"green",IF(K10<=3,"orange","#C9C21D"));"color2","#eeeeee"}),"Done"),"")
A11: FALSE | B11: Hybrid page structure: LLM-optimized first 150 words then sales copy | C11: Factual summary paragraph followed by benefit-driven marketing copy | E11: =IF(D11="Not Relevant","",IF(D11="Good","",IF(D11="Bad",1.33,1))) | G11: =IFERROR(SPARKLINE(F11,{"charttype","bar";"max",3;"min",1;"color1",IF(F11=3,"#4078DD",IF(F11=2,"#9CB7E9","#CED9EF"))}),"") | I11: =IFERROR(SPARKLINE(H11,{"charttype","bar";"max",3;"min",1;"color1",IF(H11=3,"#4078DD",IF(H11=2,"#9CB7E9","#CED9EF"))}),"") | J11: =IF(H11=1,3,IF(H11=2,2,1)) | K11: =ROUNDUP(((J11+F11)*E11),1) | L11: 8 | M11: =IFERROR(IF(A11=FALSE,SPARKLINE(K11:L11,{"charttype","bar";"max",8;"min",0;"color1",IF(K11>=5,"green",IF(K11<=3,"orange","#C9C21D"));"color2","#eeeeee"}),"Done"),"")
A12: FALSE | B12: H2/H3 hierarchy covers features, pricing, use cases | C12: Clear heading structure that LLMs can parse as distinct sections | E12: =IF(D12="Not Relevant","",IF(D12="Good","",IF(D12="Bad",1.33,1))) | G12: =IFERROR(SPARKLINE(F12,{"charttype","bar";"max",3;"min",1;"color1",IF(F12=3,"#4078DD",IF(F12=2,"#9CB7E9","#CED9EF"))}),"") | I12: =IFERROR(SPARKLINE(H12,{"charttype","bar";"max",3;"min",1;"color1",IF(H12=3,"#4078DD",IF(H12=2,"#9CB7E9","#CED9EF"))}),"") | J12: =IF(H12=1,3,IF(H12=2,2,1)) | K12: =ROUNDUP(((J12+F12)*E12),1) | L12: 8 | M12: =IFERROR(IF(A12=FALSE,SPARKLINE(K12:L12,{"charttype","bar";"max",8;"min",0;"color1",IF(K12>=5,"green",IF(K12<=3,"orange","#C9C21D"));"color2","#eeeeee"}),"Done"),"")
A13: FALSE | B13: Alt text on images includes full data context | C13: alt="Bar chart: Acme reduced processing time from 4.2h to 0.8h" | E13: =IF(D13="Not Relevant","",IF(D13="Good","",IF(D13="Bad",1.33,1))) | G13: =IFERROR(SPARKLINE(F13,{"charttype","bar";"max",3;"min",1;"color1",IF(F13=3,"#4078DD",IF(F13=2,"#9CB7E9","#CED9EF"))}),"") | I13: =IFERROR(SPARKLINE(H13,{"charttype","bar";"max",3;"min",1;"color1",IF(H13=3,"#4078DD",IF(H13=2,"#9CB7E9","#CED9EF"))}),"") | J13: =IF(H13=1,3,IF(H13=2,2,1)) | K13: =ROUNDUP(((J13+F13)*E13),1) | L13: 8 | M13: =IFERROR(IF(A13=FALSE,SPARKLINE(K13:L13,{"charttype","bar";"max",8;"min",0;"color1",IF(K13>=5,"green",IF(K13<=3,"orange","#C9C21D"));"color2","#eeeeee"}),"Done"),"")
A14: FALSE | B14: Comparison content vs top 3 competitors | C14: /vs/competitor-name pages with feature-by-feature HTML tables | E14: =IF(D14="Not Relevant","",IF(D14="Good","",IF(D14="Bad",1.33,1))) | G14: =IFERROR(SPARKLINE(F14,{"charttype","bar";"max",3;"min",1;"color1",IF(F14=3,"#4078DD",IF(F14=2,"#9CB7E9","#CED9EF"))}),"") | I14: =IFERROR(SPARKLINE(H14,{"charttype","bar";"max",3;"min",1;"color1",IF(H14=3,"#4078DD",IF(H14=2,"#9CB7E9","#CED9EF"))}),"") | J14: =IF(H14=1,3,IF(H14=2,2,1)) | K14: =ROUNDUP(((J14+F14)*E14),1) | L14: 8 | M14: =IFERROR(IF(A14=FALSE,SPARKLINE(K14:L14,{"charttype","bar";"max",8;"min",0;"color1",IF(K14>=5,"green",IF(K14<=3,"orange","#C9C21D"));"color2","#eeeeee"}),"Done"),"")
... A20: FALSE | B20: Statistics cited with verifiable sources | C20: According to Forrester (2024), companies using Acme see 3.2x ROI | E20: =IF(D20="Not Relevant","",IF(D20="Good","",IF(D20="Bad",1.33,1))) | G20: =IFERROR(SPARKLINE(F20,{"charttype","bar";"max",3;"min",1;"color1",IF(F20=3,"#4078DD",IF(F20=2,"#9CB7E9","#CED9EF"))}),"") | I20: =IFERROR(SPARKLINE(H20,{"charttype","bar";"max",3;"min",1;"color1",IF(H20=3,"#4078DD",IF(H20=2,"#9CB7E9","#CED9EF"))}),"") | J20: =IF(H20=1,3,IF(H20=2,2,1)) | K20: =ROUNDUP(((J20+F20)*E20),1) | L20: 8 | M20: =IFERROR(IF(A20=FALSE,SPARKLINE(K20:L20,{"charttype","bar";"max",8;"min",0;"color1",IF(K20>=5,"green",IF(K20<=3,"orange","#C9C21D"));"color2","#eeeeee"}),"Done"),"")

Sheet Trust and Authority
B1: Trust and Authority - AEO Checkpoint | C1: Example | D1: Evaluation | E1: Factor | F1: Impact | G1: Impact | H1: Cost | I1: Cost | J1: Cost for Sum | K1: Sum | L1: Max | M1: Priority
B2: Trust and Authority
A3: FALSE | B3: Google Business Profile claimed and fully completed | C3: All fields filled including category, description, hours, photos | E3: =IF(D3="Not Relevant","",IF(D3="Good","",IF(D3="Bad",1.33,1))) | G3: =IFERROR(SPARKLINE(F3,{"charttype","bar";"max",3;"min",1;"color1",IF(F3=3,"#4078DD",IF(F3=2,"#9CB7E9","#CED9EF"))}),"") | I3: =IFERROR(SPARKLINE(H3,{"charttype","bar";"max",3;"min",1;"color1",IF(H3=3,"#4078DD",IF(H3=2,"#9CB7E9","#CED9EF"))}),"") | J3: =IF(H3=1,3,IF(H3=2,2,1)) | K3: =ROUNDUP(((J3+F3)*E3),1) | L3: 8 | M3: =IFERROR(IF(A3=FALSE,SPARKLINE(K3:L3,{"charttype","bar";"max",8;"min",0;"color1",IF(K3>=5,"green",IF(K3<=3,"orange","#C9C21D"));"color2","#eeeeee"}),"Done"),"")
A4: FALSE | B4: Crunchbase profile created with accurate data | C4: Company description matches website positioning exactly | E4: =IF(D4="Not Relevant","",IF(D4="Good","",IF(D4="Bad",1.33,1))) | G4: =IFERROR(SPARKLINE(F4,{"charttype","bar";"max",3;"min",1;"color1",IF(F4=3,"#4078DD",IF(F4=2,"#9CB7E9","#CED9EF"))}),"") | I4: =IFERROR(SPARKLINE(H4,{"charttype","bar";"max",3;"min",1;"color1",IF(H4=3,"#4078DD",IF(H4=2,"#9CB7E9","#CED9EF"))}),"") | J4: =IF(H4=1,3,IF(H4=2,2,1)) | K4: =ROUNDUP(((J4+F4)*E4),1) | L4: 8 | M4: =IFERROR(IF(A4=FALSE,SPARKLINE(K4:L4,{"charttype","bar";"max",8;"min",0;"color1",IF(K4>=5,"green",IF(K4<=3,"orange","#C9C21D"));"color2","#eeeeee"}),"Done"),"")
A5: FALSE | B5: LinkedIn company page created with aligned phrasing | C5: About section uses same category language as website first 50 words | E5: =IF(D5="Not Relevant","",IF(D5="Good","",IF(D5="Bad",1.33,1))) | G5: =IFERROR(SPARKLINE(F5,{"charttype","bar";"max",3;"min",1;"color1",IF(F5=3,"#4078DD",IF(F5=2,"#9CB7E9","#CED9EF"))}),"") | I5: =IFERROR(SPARKLINE(H5,{"charttype","bar";"max",3;"min",1;"color1",IF(H5=3,"#4078DD",IF(H5=2,"#9CB7E9","#CED9EF"))}),"") | J5: =IF(H5=1,3,IF(H5=2,2,1)) | K5: =ROUNDUP(((J5+F5)*E5),1) | L5: 8 | M5: =IFERROR(IF(A5=FALSE,SPARKLINE(K5:L5,{"charttype","bar";"max",8;"min",0;"color1",IF(K5>=5,"green",IF(K5<=3,"orange","#C9C21D"));"color2","#eeeeee"}),"Done"),"")
A6: FALSE | B6: G2 profile created and optimized (B2B) | C6: Category listing matches target discovery queries | E6: =IF(D6="Not Relevant","",IF(D6="Good","",IF(D6="Bad",1.33,1))) | G6: =IFERROR(SPARKLINE(F6,{"charttype","bar";"max",3;"min",1;"color1",IF(F6=3,"#4078DD",IF(F6=2,"#9CB7E9","#CED9EF"))}),"") | I6: =IFERROR(SPARKLINE(H6,{"charttype","bar";"max",3;"min",1;"color1",IF(H6=3,"#4078DD",IF(H6=2,"#9CB7E9","#CED9EF"))}),"") | J6: =IF(H6=1,3,IF(H6=2,2,1)) | K6: =ROUNDUP(((J6+F6)*E6),1) | L6: 8 | M6: =IFERROR(IF(A6=FALSE,SPARKLINE(K6:L6,{"charttype","bar";"max",8;"min",0;"color1",IF(K6>=5,"green",IF(K6<=3,"orange","#C9C21D"));"color2","#eeeeee"}),"Done"),"")
A7: FALSE | B7: Capterra profile created with accurate info | C7: Description and category aligned with brand positioning | E7: =IF(D7="Not Relevant","",IF(D7="Good","",IF(D7="Bad",1.33,1))) | G7: =IFERROR(SPARKLINE(F7,{"charttype","bar";"max",3;"min",1;"color1",IF(F7=3,"#4078DD",IF(F7=2,"#9CB7E9","#CED9EF"))}),"") | I7: =IFERROR(SPARKLINE(H7,{"charttype","bar";"max",3;"min",1;"color1",IF(H7=3,"#4078DD",IF(H7=2,"#9CB7E9","#CED9EF"))}),"") | J7: =IF(H7=1,3,IF(H7=2,2,1)) | K7: =ROUNDUP(((J7+F7)*E7),1) | L7: 8 | M7: =IFERROR(IF(A7=FALSE,SPARKLINE(K7:L7,{"charttype","bar";"max",8;"min",0;"color1",IF(K7>=5,"green",IF(K7<=3,"orange","#C9C21D"));"color2","#eeeeee"}),"Done"),"")
A8: FALSE | B8: Trustpilot profile claimed | C8: Active review collection from verified customers | E8: =IF(D8="Not Relevant","",IF(D8="Good","",IF(D8="Bad",1.33,1))) | G8: =IFERROR(SPARKLINE(F8,{"charttype","bar";"max",3;"min",1;"color1",IF(F8=3,"#4078DD",IF(F8=2,"#9CB7E9","#CED9EF"))}),"") | I8: =IFERROR(SPARKLINE(H8,{"charttype","bar";"max",3;"min",1;"color1",IF(H8=3,"#4078DD",IF(H8=2,"#9CB7E9","#CED9EF"))}),"") | J8: =IF(H8=1,3,IF(H8=2,2,1)) | K8: =ROUNDUP(((J8+F8)*E8),1) | L8: 8 | M8: =IFERROR(IF(A8=FALSE,SPARKLINE(K8:L8,{"charttype","bar";"max",8;"min",0;"color1",IF(K8>=5,"green",IF(K8<=3,"orange","#C9C21D"));"color2","#eeeeee"}),"Done"),"")
A9: FALSE | B9: Product Hunt listing created | C9: Launch page with clear product description | E9: =IF(D9="Not Relevant","",IF(D9="Good","",IF(D9="Bad",1.33,1))) | G9: =IFERROR(SPARKLINE(F9,{"charttype","bar";"max",3;"min",1;"color1",IF(F9=3,"#4078DD",IF(F9=2,"#9CB7E9","#CED9EF"))}),"") | I9: =IFERROR(SPARKLINE(H9,{"charttype","bar";"max",3;"min",1;"color1",IF(H9=3,"#4078DD",IF(H9=2,"#9CB7E9","#CED9EF"))}),"") | J9: =IF(H9=1,3,IF(H9=2,2,1)) | K9: =ROUNDUP(((J9+F9)*E9),1) | L9: 8 | M9: =IFERROR(IF(A9=FALSE,SPARKLINE(K9:L9,{"charttype","bar";"max",8;"min",0;"color1",IF(K9>=5,"green",IF(K9<=3,"orange","#C9C21D"));"color2","#eeeeee"}),"Done"),"")
A10: FALSE | B10: AlternativeTo listing created | C10: Listed as alternative to top competitors in category | E10: =IF(D10="Not Relevant","",IF(D10="Good","",IF(D10="Bad",1.33,1))) | G10: =IFERROR(SPARKLINE(F10,{"charttype","bar";"max",3;"min",1;"color1",IF(F10=3,"#4078DD",IF(F10=2,"#9CB7E9","#CED9EF"))}),"") | I10: =IFERROR(SPARKLINE(H10,{"charttype","bar";"max",3;"min",1;"color1",IF(H10=3,"#4078DD",IF(H10=2,"#9CB7E9","#CED9EF"))}),"") | J10: =IF(H10=1,3,IF(H10=2,2,1)) | K10: =ROUNDUP(((J10+F10)*E10),1) | L10: 8 | M10: =IFERROR(IF(A10=FALSE,SPARKLINE(K10:L10,{"charttype","bar";"max",8;"min",0;"color1",IF(K10>=5,"green",IF(K10<=3,"orange","#C9C21D"));"color2","#eeeeee"}),"Done"),"")
A11: FALSE | B11: Wikipedia or Wikidata presence (if brand is notable) | C11: Wikidata entity with correct structured data | E11: =IF(D11="Not Relevant","",IF(D11="Good","",IF(D11="Bad",1.33,1))) | G11: =IFERROR(SPARKLINE(F11,{"charttype","bar";"max",3;"min",1;"color1",IF(F11=3,"#4078DD",IF(F11=2,"#9CB7E9","#CED9EF"))}),"") | I11: =IFERROR(SPARKLINE(H11,{"charttype","bar";"max",3;"min",1;"color1",IF(H11=3,"#4078DD",IF(H11=2,"#9CB7E9","#CED9EF"))}),"") | J11: =IF(H11=1,3,IF(H11=2,2,1)) | K11: =ROUNDUP(((J11+F11)*E11),1) | L11: 8 | M11: =IFERROR(IF(A11=FALSE,SPARKLINE(K11:L11,{"charttype","bar";"max",8;"min",0;"color1",IF(K11>=5,"green",IF(K11<=3,"orange","#C9C21D"));"color2","#eeeeee"}),"Done"),"")
A12: FALSE | B12: Phrase alignment verified across all external platforms | C12: Exact same category language on website, G2, LinkedIn, Crunchbase, GBP | E12: =IF(D12="Not Relevant","",IF(D12="Good","",IF(D12="Bad",1.33,1))) | G12: =IFERROR(SPARKLINE(F12,{"charttype","bar";"max",3;"min",1;"color1",IF(F12=3,"#4078DD",IF(F12=2,"#9CB7E9","#CED9EF"))}),"") | I12: =IFERROR(SPARKLINE(H12,{"charttype","bar";"max",3;"min",1;"color1",IF(H12=3,"#4078DD",IF(H12=2,"#9CB7E9","#CED9EF"))}),"") | J12: =IF(H12=1,3,IF(H12=2,2,1)) | K12: =ROUNDUP(((J12+F12)*E12),1) | L12: 8 | M12: =IFERROR(IF(A12=FALSE,SPARKLINE(K12:L12,{"charttype","bar";"max",8;"min",0;"color1",IF(K12>=5,"green",IF(K12<=3,"orange","#C9C21D"));"color2","#eeeeee"}),"Done"),"")
A13: FALSE | B13: 3+ external sources repeat core brand claim (Consensus Campaign) | C13: G2, Crunchbase, and industry blog all say "Acme is a B2B sales platform" | E13: =IF(D13="Not Relevant","",IF(D13="Good","",IF(D13="Bad",1.33,1))) | G13: =IFERROR(SPARKLINE(F13,{"charttype","bar";"max",3;"min",1;"color1",IF(F13=3,"#4078DD",IF(F13=2,"#9CB7E9","#CED9EF"))}),"") | I13: =IFERROR(SPARKLINE(H13,{"charttype","bar";"max",3;"min",1;"color1",IF(H13=3,"#4078DD",IF(H13=2,"#9CB7E9","#CED9EF"))}),"") | J13: =IF(H13=1,3,IF(H13=2,2,1)) | K13: =ROUNDUP(((J13+F13)*E13),1) | L13: 8 | M13: =IFERROR(IF(A13=FALSE,SPARKLINE(K13:L13,{"charttype","bar";"max",8;"min",0;"color1",IF(K13>=5,"green",IF(K13<=3,"orange","#C9C21D"));"color2","#eeeeee"}),"Done"),"")
A14: FALSE | B14: Press release distributed with brand positioning language | C14: PR wire release using exact brand category phrasing | E14: =IF(D14="Not Relevant","",IF(D14="Good","",IF(D14="Bad",1.33,1))) | G14: =IFERROR(SPARKLINE(F14,{"charttype","bar";"max",3;"min",1;"color1",IF(F14=3,"#4078DD",IF(F14=2,"#9CB7E9","#CED9EF"))}),"") | I14: =IFERROR(SPARKLINE(H14,{"charttype","bar";"max",3;"min",1;"color1",IF(H14=3,"#4078DD",IF(H14=2,"#9CB7E9","#CED9EF"))}),"") | J14: =IF(H14=1,3,IF(H14=2,2,1)) | K14: =ROUNDUP(((J14+F14)*E14),1) | L14: 8 | M14: =IFERROR(IF(A14=FALSE,SPARKLINE(K14:L14,{"charttype","bar";"max",8;"min",0;"color1",IF(K14>=5,"green",IF(K14<=3,"orange","#C9C21D"));"color2","#eeeeee"}),"Done"),"")
... A17: FALSE | B17: Backlinks from topically-relevant authoritative sites | C17: Guest posts or features on industry publications, not random directories | E17: =IF(D17="Not Relevant","",IF(D17="Good","",IF(D17="Bad",1.33,1))) | G17: =IFERROR(SPARKLINE(F17,{"charttype","bar";"max",3;"min",1;"color1",IF(F17=3,"#4078DD",IF(F17=2,"#9CB7E9","#CED9EF"))}),"") | I17: =IFERROR(SPARKLINE(H17,{"charttype","bar";"max",3;"min",1;"color1",IF(H17=3,"#4078DD",IF(H17=2,"#9CB7E9","#CED9EF"))}),"") | J17: =IF(H17=1,3,IF(H17=2,2,1)) | K17: =ROUNDUP(((J17+F17)*E17),1) | L17: 8 | M17: =IFERROR(IF(A17=FALSE,SPARKLINE(K17:L17,{"charttype","bar";"max",8;"min",0;"color1",IF(K17>=5,"green",IF(K17<=3,"orange","#C9C21D"));"color2","#eeeeee"}),"Done"),"")

Sheet LLM-Specific Optimization
B1: LLM-Specific Optimization - AEO Checkpoint | C1: Example | D1: Evaluation | E1: Factor | F1: Impact | G1: Impact | H1: Cost | I1: Cost | J1: Cost for Sum | K1: Sum | L1: Max | M1: Priority
B2: LLM-Specific Optimization
A3: FALSE | B3: ChatGPT: Bing Webmaster Tools verified | C3: Site verified and sitemap submitted in Bing Webmaster Tools | E3: =IF(D3="Not Relevant","",IF(D3="Good","",IF(D3="Bad",1.33,1))) | G3: =IFERROR(SPARKLINE(F3,{"charttype","bar";"max",3;"min",1;"color1",IF(F3=3,"#4078DD",IF(F3=2,"#9CB7E9","#CED9EF"))}),"") | I3: =IFERROR(SPARKLINE(H3,{"charttype","bar";"max",3;"min",1;"color1",IF(H3=3,"#4078DD",IF(H3=2,"#9CB7E9","#CED9EF"))}),"") | J3: =IF(H3=1,3,IF(H3=2,2,1)) | K3: =ROUNDUP(((J3+F3)*E3),1) | L3: 8 | M3: =IFERROR(IF(A3=FALSE,SPARKLINE(K3:L3,{"charttype","bar";"max",8;"min",0;"color1",IF(K3>=5,"green",IF(K3<=3,"orange","#C9C21D"));"color2","#eeeeee"}),"Done"),"")
A4: FALSE | B4: ChatGPT: OAI-SearchBot crawling confirmed in server logs | C4: Log entries showing OAI-SearchBot user agent accessing key pages | E4: =IF(D4="Not Relevant","",IF(D4="Good","",IF(D4="Bad",1.33,1))) | G4: =IFERROR(SPARKLINE(F4,{"charttype","bar";"max",3;"min",1;"color1",IF(F4=3,"#4078DD",IF(F4=2,"#9CB7E9","#CED9EF"))}),"") | I4: =IFERROR(SPARKLINE(H4,{"charttype","bar";"max",3;"min",1;"color1",IF(H4=3,"#4078DD",IF(H4=2,"#9CB7E9","#CED9EF"))}),"") | J4: =IF(H4=1,3,IF(H4=2,2,1)) | K4: =ROUNDUP(((J4+F4)*E4),1) | L4: 8 | M4: =IFERROR(IF(A4=FALSE,SPARKLINE(K4:L4,{"charttype","bar";"max",8;"min",0;"color1",IF(K4>=5,"green",IF(K4<=3,"orange","#C9C21D"));"color2","#eeeeee"}),"Done"),"")
A5: FALSE | B5: ChatGPT: Key pages force-fetched via prompt | C5: Ask ChatGPT: "Search [url] and summarize" for each critical page | E5: =IF(D5="Not Relevant","",IF(D5="Good","",IF(D5="Bad",1.33,1))) | G5: =IFERROR(SPARKLINE(F5,{"charttype","bar";"max",3;"min",1;"color1",IF(F5=3,"#4078DD",IF(F5=2,"#9CB7E9","#CED9EF"))}),"") | I5: =IFERROR(SPARKLINE(H5,{"charttype","bar";"max",3;"min",1;"color1",IF(H5=3,"#4078DD",IF(H5=2,"#9CB7E9","#CED9EF"))}),"") | J5: =IF(H5=1,3,IF(H5=2,2,1)) | K5: =ROUNDUP(((J5+F5)*E5),1) | L5: 8 | M5: =IFERROR(IF(A5=FALSE,SPARKLINE(K5:L5,{"charttype","bar";"max",8;"min",0;"color1",IF(K5>=5,"green",IF(K5<=3,"orange","#C9C21D"));"color2","#eeeeee"}),"Done"),"")
A6: FALSE | B6: ChatGPT: Cache fingerprint checked (utm_source=openai = stale) | C6: If ChatGPT cites URL with utm_source=openai the cache is from Bing not fresh | E6: =IF(D6="Not Relevant","",IF(D6="Good","",IF(D6="Bad",1.33,1))) | G6: =IFERROR(SPARKLINE(F6,{"charttype","bar";"max",3;"min",1;"color1",IF(F6=3,"#4078DD",IF(F6=2,"#9CB7E9","#CED9EF"))}),"") | I6: =IFERROR(SPARKLINE(H6,{"charttype","bar";"max",3;"min",1;"color1",IF(H6=3,"#4078DD",IF(H6=2,"#9CB7E9","#CED9EF"))}),"") | J6: =IF(H6=1,3,IF(H6=2,2,1)) | K6: =ROUNDUP(((J6+F6)*E6),1) | L6: 8 | M6: =IFERROR(IF(A6=FALSE,SPARKLINE(K6:L6,{"charttype","bar";"max",8;"min",0;"color1",IF(K6>=5,"green",IF(K6<=3,"orange","#C9C21D"));"color2","#eeeeee"}),"Done"),"")
A7: FALSE | B7: ChatGPT: Cache-busting used after content updates | C7: Append ?v=new to URLs and re-fetch after major content changes | E7: =IF(D7="Not Relevant","",IF(D7="Good","",IF(D7="Bad",1.33,1))) | G7: =IFERROR(SPARKLINE(F7,{"charttype","bar";"max",3;"min",1;"color1",IF(F7=3,"#4078DD",IF(F7=2,"#9CB7E9","#CED9EF"))}),"") | I7: =IFERROR(SPARKLINE(H7,{"charttype","bar";"max",3;"min",1;"color1",IF(H7=3,"#4078DD",IF(H7=2,"#9CB7E9","#CED9EF"))}),"") | J7: =IF(H7=1,3,IF(H7=2,2,1)) | K7: =ROUNDUP(((J7+F7)*E7),1) | L7: 8 | M7: =IFERROR(IF(A7=FALSE,SPARKLINE(K7:L7,{"charttype","bar";"max",8;"min",0;"color1",IF(K7>=5,"green",IF(K7<=3,"orange","#C9C21D"));"color2","#eeeeee"}),"Done"),"")
A8: FALSE | B8: Gemini: Google Search Console verified | C8: Site verified with all sitemaps submitted | E8: =IF(D8="Not Relevant","",IF(D8="Good","",IF(D8="Bad",1.33,1))) | G8: =IFERROR(SPARKLINE(F8,{"charttype","bar";"max",3;"min",1;"color1",IF(F8=3,"#4078DD",IF(F8=2,"#9CB7E9","#CED9EF"))}),"") | I8: =IFERROR(SPARKLINE(H8,{"charttype","bar";"max",3;"min",1;"color1",IF(H8=3,"#4078DD",IF(H8=2,"#9CB7E9","#CED9EF"))}),"") | J8: =IF(H8=1,3,IF(H8=2,2,1)) | K8: =ROUNDUP(((J8+F8)*E8),1) | L8: 8 | M8: =IFERROR(IF(A8=FALSE,SPARKLINE(K8:L8,{"charttype","bar";"max",8;"min",0;"color1",IF(K8>=5,"green",IF(K8<=3,"orange","#C9C21D"));"color2","#eeeeee"}),"Done"),"")
A9: FALSE | B9: Gemini: E-E-A-T signals strong across site | C9: Author bios, about page, credentials, external validation present | E9: =IF(D9="Not Relevant","",IF(D9="Good","",IF(D9="Bad",1.33,1))) | G9: =IFERROR(SPARKLINE(F9,{"charttype","bar";"max",3;"min",1;"color1",IF(F9=3,"#4078DD",IF(F9=2,"#9CB7E9","#CED9EF"))}),"") | I9: =IFERROR(SPARKLINE(H9,{"charttype","bar";"max",3;"min",1;"color1",IF(H9=3,"#4078DD",IF(H9=2,"#9CB7E9","#CED9EF"))}),"") | J9: =IF(H9=1,3,IF(H9=2,2,1)) | K9: =ROUNDUP(((J9+F9)*E9),1) | L9: 8 | M9: =IFERROR(IF(A9=FALSE,SPARKLINE(K9:L9,{"charttype","bar";"max",8;"min",0;"color1",IF(K9>=5,"green",IF(K9<=3,"orange","#C9C21D"));"color2","#eeeeee"}),"Done"),"")
A10: FALSE | B10: Gemini: Grounding Blocks on key pages (HTML tables with stats) | C10: <table> elements with numerical data that Gemini can ground against | E10: =IF(D10="Not Relevant","",IF(D10="Good","",IF(D10="Bad",1.33,1))) | G10: =IFERROR(SPARKLINE(F10,{"charttype","bar";"max",3;"min",1;"color1",IF(F10=3,"#4078DD",IF(F10=2,"#9CB7E9","#CED9EF"))}),"") | I10: =IFERROR(SPARKLINE(H10,{"charttype","bar";"max",3;"min",1;"color1",IF(H10=3,"#4078DD",IF(H10=2,"#9CB7E9","#CED9EF"))}),"") | J10: =IF(H10=1,3,IF(H10=2,2,1)) | K10: =ROUNDUP(((J10+F10)*E10),1) | L10: 8 | M10: =IFERROR(IF(A10=FALSE,SPARKLINE(K10:L10,{"charttype","bar";"max",8;"min",0;"color1",IF(K10>=5,"green",IF(K10<=3,"orange","#C9C21D"));"color2","#eeeeee"}),"Done"),"")
A11: FALSE | B11: Gemini: Top 10 Google ranking for entity queries | C11: Brand name + category query ranks on page 1 of Google | E11: =IF(D11="Not Relevant","",IF(D11="Good","",IF(D11="Bad",1.33,1))) | G11: =IFERROR(SPARKLINE(F11,{"charttype","bar";"max",3;"min",1;"color1",IF(F11=3,"#4078DD",IF(F11=2,"#9CB7E9","#CED9EF"))}),"") | I11: =IFERROR(SPARKLINE(H11,{"charttype","bar";"max",3;"min",1;"color1",IF(H11=3,"#4078DD",IF(H11=2,"#9CB7E9","#CED9EF"))}),"") | J11: =IF(H11=1,3,IF(H11=2,2,1)) | K11: =ROUNDUP(((J11+F11)*E11),1) | L11: 8 | M11: =IFERROR(IF(A11=FALSE,SPARKLINE(K11:L11,{"charttype","bar";"max",8;"min",0;"color1",IF(K11>=5,"green",IF(K11<=3,"orange","#C9C21D"));"color2","#eeeeee"}),"Done"),"")
A12: FALSE | B12: Gemini: Statistics with verifiable sources on key pages | C12: Numbers cited with source: "According to [Source], [Year]" | E12: =IF(D12="Not Relevant","",IF(D12="Good","",IF(D12="Bad",1.33,1))) | G12: =IFERROR(SPARKLINE(F12,{"charttype","bar";"max",3;"min",1;"color1",IF(F12=3,"#4078DD",IF(F12=2,"#9CB7E9","#CED9EF"))}),"") | I12: =IFERROR(SPARKLINE(H12,{"charttype","bar";"max",3;"min",1;"color1",IF(H12=3,"#4078DD",IF(H12=2,"#9CB7E9","#CED9EF"))}),"") | J12: =IF(H12=1,3,IF(H12=2,2,1)) | K12: =ROUNDUP(((J12+F12)*E12),1) | L12: 8 | M12: =IFERROR(IF(A12=FALSE,SPARKLINE(K12:L12,{"charttype","bar";"max",8;"min",0;"color1",IF(K12>=5,"green",IF(K12<=3,"orange","#C9C21D"));"color2","#eeeeee"}),"Done"),"")
A13: FALSE | B13: Perplexity: Top Google results for target queries | C13: Key pages rank well in Google (Perplexity pulls from top results) | E13: =IF(D13="Not Relevant","",IF(D13="Good","",IF(D13="Bad",1.33,1))) | G13: =IFERROR(SPARKLINE(F13,{"charttype","bar";"max",3;"min",1;"color1",IF(F13=3,"#4078DD",IF(F13=2,"#9CB7E9","#CED9EF"))}),"") | I13: =IFERROR(SPARKLINE(H13,{"charttype","bar";"max",3;"min",1;"color1",IF(H13=3,"#4078DD",IF(H13=2,"#9CB7E9","#CED9EF"))}),"") | J13: =IF(H13=1,3,IF(H13=2,2,1)) | K13: =ROUNDUP(((J13+F13)*E13),1) | L13: 8 | M13: =IFERROR(IF(A13=FALSE,SPARKLINE(K13:L13,{"charttype","bar";"max",8;"min",0;"color1",IF(K13>=5,"green",IF(K13<=3,"orange","#C9C21D"));"color2","#eeeeee"}),"Done"),"")
A14: FALSE | B14: Perplexity: Citation-friendly content structure | C14: Clear factual statements that are easy to cite with source attribution | E14: =IF(D14="Not Relevant","",IF(D14="Good","",IF(D14="Bad",1.33,1))) | G14: =IFERROR(SPARKLINE(F14,{"charttype","bar";"max",3;"min",1;"color1",IF(F14=3,"#4078DD",IF(F14=2,"#9CB7E9","#CED9EF"))}),"") | I14: =IFERROR(SPARKLINE(H14,{"charttype","bar";"max",3;"min",1;"color1",IF(H14=3,"#4078DD",IF(H14=2,"#9CB7E9","#CED9EF"))}),"") | J14: =IF(H14=1,3,IF(H14=2,2,1)) | K14: =ROUNDUP(((J14+F14)*E14),1) | L14: 8 | M14: =IFERROR(IF(A14=FALSE,SPARKLINE(K14:L14,{"charttype","bar";"max",8;"min",0;"color1",IF(K14>=5,"green",IF(K14<=3,"orange","#C9C21D"));"color2","#eeeeee"}),"Done"),"")
... A20: FALSE | B20: All LLMs: Per-page force-fetch after ANY content update | C20: Every content change triggers individual page re-fetch across all LLMs | E20: =IF(D20="Not Relevant","",IF(D20="Good","",IF(D20="Bad",1.33,1))) | G20: =IFERROR(SPARKLINE(F20,{"charttype","bar";"max",3;"min",1;"color1",IF(F20=3,"#4078DD",IF(F20=2,"#9CB7E9","#CED9EF"))}),"") | I20: =IFERROR(SPARKLINE(H20,{"charttype","bar";"max",3;"min",1;"color1",IF(H20=3,"#4078DD",IF(H20=2,"#9CB7E9","#CED9EF"))}),"") | J20: =IF(H20=1,3,IF(H20=2,2,1)) | K20: =ROUNDUP(((J20+F20)*E20),1) | L20: 8 | M20: =IFERROR(IF(A20=FALSE,SPARKLINE(K20:L20,{"charttype","bar";"max",8;"min",0;"color1",IF(K20>=5,"green",IF(K20<=3,"orange","#C9C21D"));"color2","#eeeeee"}),"Done"),"")

Sheet Monitoring and Analytics
B1: Monitoring and Analytics - AEO Checkpoint | C1: Example | D1: Evaluation | E1: Factor | F1: Impact | G1: Impact | H1: Cost | I1: Cost | J1: Cost for Sum | K1: Sum | L1: Max | M1: Priority
B2: Monitoring and Analytics
A3: FALSE | B3: Weekly LLM citation check across all major LLMs | C3: Every Monday: ask branded + discovery queries on ChatGPT, Gemini, Perplexity, Claude | E3: =IF(D3="Not Relevant","",IF(D3="Good","",IF(D3="Bad",1.33,1))) | G3: =IFERROR(SPARKLINE(F3,{"charttype","bar";"max",3;"min",1;"color1",IF(F3=3,"#4078DD",IF(F3=2,"#9CB7E9","#CED9EF"))}),"") | I3: =IFERROR(SPARKLINE(H3,{"charttype","bar";"max",3;"min",1;"color1",IF(H3=3,"#4078DD",IF(H3=2,"#9CB7E9","#CED9EF"))}),"") | J3: =IF(H3=1,3,IF(H3=2,2,1)) | K3: =ROUNDUP(((J3+F3)*E3),1) | L3: 8 | M3: =IFERROR(IF(A3=FALSE,SPARKLINE(K3:L3,{"charttype","bar";"max",8;"min",0;"color1",IF(K3>=5,"green",IF(K3<=3,"orange","#C9C21D"));"color2","#eeeeee"}),"Done"),"")
A4: FALSE | B4: 10-run consistency test per key query (monthly) | C4: Run each dream query 10x per LLM and track mention rate percentage | E4: =IF(D4="Not Relevant","",IF(D4="Good","",IF(D4="Bad",1.33,1))) | G4: =IFERROR(SPARKLINE(F4,{"charttype","bar";"max",3;"min",1;"color1",IF(F4=3,"#4078DD",IF(F4=2,"#9CB7E9","#CED9EF"))}),"") | I4: =IFERROR(SPARKLINE(H4,{"charttype","bar";"max",3;"min",1;"color1",IF(H4=3,"#4078DD",IF(H4=2,"#9CB7E9","#CED9EF"))}),"") | J4: =IF(H4=1,3,IF(H4=2,2,1)) | K4: =ROUNDUP(((J4+F4)*E4),1) | L4: 8 | M4: =IFERROR(IF(A4=FALSE,SPARKLINE(K4:L4,{"charttype","bar";"max",8;"min",0;"color1",IF(K4>=5,"green",IF(K4<=3,"orange","#C9C21D"));"color2","#eeeeee"}),"Done"),"")
A5: FALSE | B5: Crawler log monitoring (OAI-SearchBot, ClaudeBot, PerplexityBot, GPTBot) | C5: Server logs filtered and alerting on AI crawler activity | E5: =IF(D5="Not Relevant","",IF(D5="Good","",IF(D5="Bad",1.33,1))) | G5: =IFERROR(SPARKLINE(F5,{"charttype","bar";"max",3;"min",1;"color1",IF(F5=3,"#4078DD",IF(F5=2,"#9CB7E9","#CED9EF"))}),"") | I5: =IFERROR(SPARKLINE(H5,{"charttype","bar";"max",3;"min",1;"color1",IF(H5=3,"#4078DD",IF(H5=2,"#9CB7E9","#CED9EF"))}),"") | J5: =IF(H5=1,3,IF(H5=2,2,1)) | K5: =ROUNDUP(((J5+F5)*E5),1) | L5: 8 | M5: =IFERROR(IF(A5=FALSE,SPARKLINE(K5:L5,{"charttype","bar";"max",8;"min",0;"color1",IF(K5>=5,"green",IF(K5<=3,"orange","#C9C21D"));"color2","#eeeeee"}),"Done"),"")
A6: FALSE | B6: Cache freshness check using utm_source=openai fingerprint | C6: If ChatGPT citations include utm_source=openai the data is stale Bing cache | E6: =IF(D6="Not Relevant","",IF(D6="Good","",IF(D6="Bad",1.33,1))) | G6: =IFERROR(SPARKLINE(F6,{"charttype","bar";"max",3;"min",1;"color1",IF(F6=3,"#4078DD",IF(F6=2,"#9CB7E9","#CED9EF"))}),"") | I6: =IFERROR(SPARKLINE(H6,{"charttype","bar";"max",3;"min",1;"color1",IF(H6=3,"#4078DD",IF(H6=2,"#9CB7E9","#CED9EF"))}),"") | J6: =IF(H6=1,3,IF(H6=2,2,1)) | K6: =ROUNDUP(((J6+F6)*E6),1) | L6: 8 | M6: =IFERROR(IF(A6=FALSE,SPARKLINE(K6:L6,{"charttype","bar";"max",8;"min",0;"color1",IF(K6>=5,"green",IF(K6<=3,"orange","#C9C21D"));"color2","#eeeeee"}),"Done"),"")
A7: FALSE | B7: GA4 AI referral tracking configured | C7: GA4 referral source report shows traffic from chatgpt.com, perplexity.ai | E7: =IF(D7="Not Relevant","",IF(D7="Good","",IF(D7="Bad",1.33,1))) | G7: =IFERROR(SPARKLINE(F7,{"charttype","bar";"max",3;"min",1;"color1",IF(F7=3,"#4078DD",IF(F7=2,"#9CB7E9","#CED9EF"))}),"") | I7: =IFERROR(SPARKLINE(H7,{"charttype","bar";"max",3;"min",1;"color1",IF(H7=3,"#4078DD",IF(H7=2,"#9CB7E9","#CED9EF"))}),"") | J7: =IF(H7=1,3,IF(H7=2,2,1)) | K7: =ROUNDUP(((J7+F7)*E7),1) | L7: 8 | M7: =IFERROR(IF(A7=FALSE,SPARKLINE(K7:L7,{"charttype","bar";"max",8;"min",0;"color1",IF(K7>=5,"green",IF(K7<=3,"orange","#C9C21D"));"color2","#eeeeee"}),"Done"),"")
A8: FALSE | B8: Competitor LLM presence monitored monthly | C8: Track which competitors appear in responses to your category queries | E8: =IF(D8="Not Relevant","",IF(D8="Good","",IF(D8="Bad",1.33,1))) | G8: =IFERROR(SPARKLINE(F8,{"charttype","bar";"max",3;"min",1;"color1",IF(F8=3,"#4078DD",IF(F8=2,"#9CB7E9","#CED9EF"))}),"") | I8: =IFERROR(SPARKLINE(H8,{"charttype","bar";"max",3;"min",1;"color1",IF(H8=3,"#4078DD",IF(H8=2,"#9CB7E9","#CED9EF"))}),"") | J8: =IF(H8=1,3,IF(H8=2,2,1)) | K8: =ROUNDUP(((J8+F8)*E8),1) | L8: 8 | M8: =IFERROR(IF(A8=FALSE,SPARKLINE(K8:L8,{"charttype","bar";"max",8;"min",0;"color1",IF(K8>=5,"green",IF(K8<=3,"orange","#C9C21D"));"color2","#eeeeee"}),"Done"),"")
A9: FALSE | B9: Hallucination baseline documented | C9: Record any inaccurate claims LLMs make about your brand as a baseline | E9: =IF(D9="Not Relevant","",IF(D9="Good","",IF(D9="Bad",1.33,1))) | G9: =IFERROR(SPARKLINE(F9,{"charttype","bar";"max",3;"min",1;"color1",IF(F9=3,"#4078DD",IF(F9=2,"#9CB7E9","#CED9EF"))}),"") | I9: =IFERROR(SPARKLINE(H9,{"charttype","bar";"max",3;"min",1;"color1",IF(H9=3,"#4078DD",IF(H9=2,"#9CB7E9","#CED9EF"))}),"") | J9: =IF(H9=1,3,IF(H9=2,2,1)) | K9: =ROUNDUP(((J9+F9)*E9),1) | L9: 8 | M9: =IFERROR(IF(A9=FALSE,SPARKLINE(K9:L9,{"charttype","bar";"max",8;"min",0;"color1",IF(K9>=5,"green",IF(K9<=3,"orange","#C9C21D"));"color2","#eeeeee"}),"Done"),"")
A10: FALSE | B10: Accuracy scoring per query tracked | C10: Score each LLM response for factual accuracy on a 1-5 scale | E10: =IF(D10="Not Relevant","",IF(D10="Good","",IF(D10="Bad",1.33,1))) | G10: =IFERROR(SPARKLINE(F10,{"charttype","bar";"max",3;"min",1;"color1",IF(F10=3,"#4078DD",IF(F10=2,"#9CB7E9","#CED9EF"))}),"") | I10: =IFERROR(SPARKLINE(H10,{"charttype","bar";"max",3;"min",1;"color1",IF(H10=3,"#4078DD",IF(H10=2,"#9CB7E9","#CED9EF"))}),"") | J10: =IF(H10=1,3,IF(H10=2,2,1)) | K10: =ROUNDUP(((J10+F10)*E10),1) | L10: 8 | M10: =IFERROR(IF(A10=FALSE,SPARKLINE(K10:L10,{"charttype","bar";"max",8;"min",0;"color1",IF(K10>=5,"green",IF(K10<=3,"orange","#C9C21D"));"color2","#eeeeee"}),"Done"),"")
A11: FALSE | B11: Citation source analysis completed | C11: Document which sources LLMs cite when mentioning your brand or category | E11: =IF(D11="Not Relevant","",IF(D11="Good","",IF(D11="Bad",1.33,1))) | G11: =IFERROR(SPARKLINE(F11,{"charttype","bar";"max",3;"min",1;"color1",IF(F11=3,"#4078DD",IF(F11=2,"#9CB7E9","#CED9EF"))}),"") | I11: =IFERROR(SPARKLINE(H11,{"charttype","bar";"max",3;"min",1;"color1",IF(H11=3,"#4078DD",IF(H11=2,"#9CB7E9","#CED9EF"))}),"") | J11: =IF(H11=1,3,IF(H11=2,2,1)) | K11: =ROUNDUP(((J11+F11)*E11),1) | L11: 8 | M11: =IFERROR(IF(A11=FALSE,SPARKLINE(K11:L11,{"charttype","bar";"max",8;"min",0;"color1",IF(K11>=5,"green",IF(K11<=3,"orange","#C9C21D"));"color2","#eeeeee"}),"Done"),"")
A12: FALSE | B12: Sentinel alerts configured for misinformation or competitor dominance | C12: Automated workflow to detect negative changes in LLM responses | E12: =IF(D12="Not Relevant","",IF(D12="Good","",IF(D12="Bad",1.33,1))) | G12: =IFERROR(SPARKLINE(F12,{"charttype","bar";"max",3;"min",1;"color1",IF(F12=3,"#4078DD",IF(F12=2,"#9CB7E9","#CED9EF"))}),"") | I12: =IFERROR(SPARKLINE(H12,{"charttype","bar";"max",3;"min",1;"color1",IF(H12=3,"#4078DD",IF(H12=2,"#9CB7E9","#CED9EF"))}),"") | J12: =IF(H12=1,3,IF(H12=2,2,1)) | K12: =ROUNDUP(((J12+F12)*E12),1) | L12: 8 | M12: =IFERROR(IF(A12=FALSE,SPARKLINE(K12:L12,{"charttype","bar";"max",8;"min",0;"color1",IF(K12>=5,"green",IF(K12<=3,"orange","#C9C21D"));"color2","#eeeeee"}),"Done"),"")
A13: FALSE | B13: Stale page force-fetch workflow documented | C13: Step-by-step runbook for forcing LLMs to re-read updated pages | E13: =IF(D13="Not Relevant","",IF(D13="Good","",IF(D13="Bad",1.33,1))) | G13: =IFERROR(SPARKLINE(F13,{"charttype","bar";"max",3;"min",1;"color1",IF(F13=3,"#4078DD",IF(F13=2,"#9CB7E9","#CED9EF"))}),"") | I13: =IFERROR(SPARKLINE(H13,{"charttype","bar";"max",3;"min",1;"color1",IF(H13=3,"#4078DD",IF(H13=2,"#9CB7E9","#CED9EF"))}),"") | J13: =IF(H13=1,3,IF(H13=2,2,1)) | K13: =ROUNDUP(((J13+F13)*E13),1) | L13: 8 | M13: =IFERROR(IF(A13=FALSE,SPARKLINE(K13:L13,{"charttype","bar";"max",8;"min",0;"color1",IF(K13>=5,"green",IF(K13<=3,"orange","#C9C21D"));"color2","#eeeeee"}),"Done"),"")
A14: FALSE | B14: Quarterly strategy review scheduled | C14: Calendar reminder for full re-audit and strategy adjustment every 90 days | E14: =IF(D14="Not Relevant","",IF(D14="Good","",IF(D14="Bad",1.33,1))) | G14: =IFERROR(SPARKLINE(F14,{"charttype","bar";"max",3;"min",1;"color1",IF(F14=3,"#4078DD",IF(F14=2,"#9CB7E9","#CED9EF"))}),"") | I14: =IFERROR(SPARKLINE(H14,{"charttype","bar";"max",3;"min",1;"color1",IF(H14=3,"#4078DD",IF(H14=2,"#9CB7E9","#CED9EF"))}),"") | J14: =IF(H14=1,3,IF(H14=2,2,1)) | K14: =ROUNDUP(((J14+F14)*E14),1) | L14: 8 | M14: =IFERROR(IF(A14=FALSE,SPARKLINE(K14:L14,{"charttype","bar";"max",8;"min",0;"color1",IF(K14>=5,"green",IF(K14<=3,"orange","#C9C21D"));"color2","#eeeeee"}),"Done"),"")

Sheet Content Strategy
B1: Content Strategy - AEO Checkpoint | C1: Example | D1: Evaluation | E1: Factor | F1: Impact | G1: Impact | H1: Cost | I1: Cost | J1: Cost for Sum | K1: Sum | L1: Max | M1: Priority
B2: Content Strategy
A3: FALSE | B3: Dream queries identified (5-10 per client) | C3: "Best CRM for startups", "affordable sales automation" | E3: =IF(D3="Not Relevant","",IF(D3="Good","",IF(D3="Bad",1.33,1))) | G3: =IFERROR(SPARKLINE(F3,{"charttype","bar";"max",3;"min",1;"color1",IF(F3=3,"#4078DD",IF(F3=2,"#9CB7E9","#CED9EF"))}),"") | I3: =IFERROR(SPARKLINE(H3,{"charttype","bar";"max",3;"min",1;"color1",IF(H3=3,"#4078DD",IF(H3=2,"#9CB7E9","#CED9EF"))}),"") | J3: =IF(H3=1,3,IF(H3=2,2,1)) | K3: =ROUNDUP(((J3+F3)*E3),1) | L3: 8 | M3: =IFERROR(IF(A3=FALSE,SPARKLINE(K3:L3,{"charttype","bar";"max",8;"min",0;"color1",IF(K3>=5,"green",IF(K3<=3,"orange","#C9C21D"));"color2","#eeeeee"}),"Done"),"")
A4: FALSE | B4: Pillar pages created for main topics | C4: /crm-for-startups with 2000+ words covering the topic comprehensively | E4: =IF(D4="Not Relevant","",IF(D4="Good","",IF(D4="Bad",1.33,1))) | G4: =IFERROR(SPARKLINE(F4,{"charttype","bar";"max",3;"min",1;"color1",IF(F4=3,"#4078DD",IF(F4=2,"#9CB7E9","#CED9EF"))}),"") | I4: =IFERROR(SPARKLINE(H4,{"charttype","bar";"max",3;"min",1;"color1",IF(H4=3,"#4078DD",IF(H4=2,"#9CB7E9","#CED9EF"))}),"") | J4: =IF(H4=1,3,IF(H4=2,2,1)) | K4: =ROUNDUP(((J4+F4)*E4),1) | L4: 8 | M4: =IFERROR(IF(A4=FALSE,SPARKLINE(K4:L4,{"charttype","bar";"max",8;"min",0;"color1",IF(K4>=5,"green",IF(K4<=3,"orange","#C9C21D"));"color2","#eeeeee"}),"Done"),"")
A5: FALSE | B5: Comparison pages for top 5 competitors | C5: /vs/salesforce and /vs/hubspot with feature-by-feature HTML tables | E5: =IF(D5="Not Relevant","",IF(D5="Good","",IF(D5="Bad",1.33,1))) | G5: =IFERROR(SPARKLINE(F5,{"charttype","bar";"max",3;"min",1;"color1",IF(F5=3,"#4078DD",IF(F5=2,"#9CB7E9","#CED9EF"))}),"") | I5: =IFERROR(SPARKLINE(H5,{"charttype","bar";"max",3;"min",1;"color1",IF(H5=3,"#4078DD",IF(H5=2,"#9CB7E9","#CED9EF"))}),"") | J5: =IF(H5=1,3,IF(H5=2,2,1)) | K5: =ROUNDUP(((J5+F5)*E5),1) | L5: 8 | M5: =IFERROR(IF(A5=FALSE,SPARKLINE(K5:L5,{"charttype","bar";"max",8;"min",0;"color1",IF(K5>=5,"green",IF(K5<=3,"orange","#C9C21D"));"color2","#eeeeee"}),"Done"),"")
A6: FALSE | B6: Feature and use case pages created | C6: /features/reporting and /use-cases/saas-companies | E6: =IF(D6="Not Relevant","",IF(D6="Good","",IF(D6="Bad",1.33,1))) | G6: =IFERROR(SPARKLINE(F6,{"charttype","bar";"max",3;"min",1;"color1",IF(F6=3,"#4078DD",IF(F6=2,"#9CB7E9","#CED9EF"))}),"") | I6: =IFERROR(SPARKLINE(H6,{"charttype","bar";"max",3;"min",1;"color1",IF(H6=3,"#4078DD",IF(H6=2,"#9CB7E9","#CED9EF"))}),"") | J6: =IF(H6=1,3,IF(H6=2,2,1)) | K6: =ROUNDUP(((J6+F6)*E6),1) | L6: 8 | M6: =IFERROR(IF(A6=FALSE,SPARKLINE(K6:L6,{"charttype","bar";"max",8;"min",0;"color1",IF(K6>=5,"green",IF(K6<=3,"orange","#C9C21D"));"color2","#eeeeee"}),"Done"),"")
A7: FALSE | B7: /pricing page with clear tiers in HTML text | C7: Starter $49/mo, Pro $99/mo, Enterprise $299/mo in a table | E7: =IF(D7="Not Relevant","",IF(D7="Good","",IF(D7="Bad",1.33,1))) | G7: =IFERROR(SPARKLINE(F7,{"charttype","bar";"max",3;"min",1;"color1",IF(F7=3,"#4078DD",IF(F7=2,"#9CB7E9","#CED9EF"))}),"") | I7: =IFERROR(SPARKLINE(H7,{"charttype","bar";"max",3;"min",1;"color1",IF(H7=3,"#4078DD",IF(H7=2,"#9CB7E9","#CED9EF"))}),"") | J7: =IF(H7=1,3,IF(H7=2,2,1)) | K7: =ROUNDUP(((J7+F7)*E7),1) | L7: 8 | M7: =IFERROR(IF(A7=FALSE,SPARKLINE(K7:L7,{"charttype","bar";"max",8;"min",0;"color1",IF(K7>=5,"green",IF(K7<=3,"orange","#C9C21D"));"color2","#eeeeee"}),"Done"),"")
A8: FALSE | B8: /features overview page with structured sections | C8: Each feature as H2 with description and specific metrics | E8: =IF(D8="Not Relevant","",IF(D8="Good","",IF(D8="Bad",1.33,1))) | G8: =IFERROR(SPARKLINE(F8,{"charttype","bar";"max",3;"min",1;"color1",IF(F8=3,"#4078DD",IF(F8=2,"#9CB7E9","#CED9EF"))}),"") | I8: =IFERROR(SPARKLINE(H8,{"charttype","bar";"max",3;"min",1;"color1",IF(H8=3,"#4078DD",IF(H8=2,"#9CB7E9","#CED9EF"))}),"") | J8: =IF(H8=1,3,IF(H8=2,2,1)) | K8: =ROUNDUP(((J8+F8)*E8),1) | L8: 8 | M8: =IFERROR(IF(A8=FALSE,SPARKLINE(K8:L8,{"charttype","bar";"max",8;"min",0;"color1",IF(K8>=5,"green",IF(K8<=3,"orange","#C9C21D"));"color2","#eeeeee"}),"Done"),"")
A9: FALSE | B9: Glossary terms for industry keywords | C9: /glossary/sales-automation with clear definitions LLMs can extract | E9: =IF(D9="Not Relevant","",IF(D9="Good","",IF(D9="Bad",1.33,1))) | G9: =IFERROR(SPARKLINE(F9,{"charttype","bar";"max",3;"min",1;"color1",IF(F9=3,"#4078DD",IF(F9=2,"#9CB7E9","#CED9EF"))}),"") | I9: =IFERROR(SPARKLINE(H9,{"charttype","bar";"max",3;"min",1;"color1",IF(H9=3,"#4078DD",IF(H9=2,"#9CB7E9","#CED9EF"))}),"") | J9: =IF(H9=1,3,IF(H9=2,2,1)) | K9: =ROUNDUP(((J9+F9)*E9),1) | L9: 8 | M9: =IFERROR(IF(A9=FALSE,SPARKLINE(K9:L9,{"charttype","bar";"max",8;"min",0;"color1",IF(K9>=5,"green",IF(K9<=3,"orange","#C9C21D"));"color2","#eeeeee"}),"Done"),"")
A10: FALSE | B10: Zero-volume keywords researched (forums, support tickets, Reddit) | C10: Identify questions people ask but don't search for on Google | E10: =IF(D10="Not Relevant","",IF(D10="Good","",IF(D10="Bad",1.33,1))) | G10: =IFERROR(SPARKLINE(F10,{"charttype","bar";"max",3;"min",1;"color1",IF(F10=3,"#4078DD",IF(F10=2,"#9CB7E9","#CED9EF"))}),"") | I10: =IFERROR(SPARKLINE(H10,{"charttype","bar";"max",3;"min",1;"color1",IF(H10=3,"#4078DD",IF(H10=2,"#9CB7E9","#CED9EF"))}),"") | J10: =IF(H10=1,3,IF(H10=2,2,1)) | K10: =ROUNDUP(((J10+F10)*E10),1) | L10: 8 | M10: =IFERROR(IF(A10=FALSE,SPARKLINE(K10:L10,{"charttype","bar";"max",8;"min",0;"color1",IF(K10>=5,"green",IF(K10<=3,"orange","#C9C21D"));"color2","#eeeeee"}),"Done"),"")
A11: FALSE | B11: Content lifecycle phase identified (Create / Grow / Optimize / Expand) | C11: Map each page to its lifecycle stage to prioritize actions | E11: =IF(D11="Not Relevant","",IF(D11="Good","",IF(D11="Bad",1.33,1))) | G11: =IFERROR(SPARKLINE(F11,{"charttype","bar";"max",3;"min",1;"color1",IF(F11=3,"#4078DD",IF(F11=2,"#9CB7E9","#CED9EF"))}),"") | I11: =IFERROR(SPARKLINE(H11,{"charttype","bar";"max",3;"min",1;"color1",IF(H11=3,"#4078DD",IF(H11=2,"#9CB7E9","#CED9EF"))}),"") | J11: =IF(H11=1,3,IF(H11=2,2,1)) | K11: =ROUNDUP(((J11+F11)*E11),1) | L11: 8 | M11: =IFERROR(IF(A11=FALSE,SPARKLINE(K11:L11,{"charttype","bar";"max",8;"min",0;"color1",IF(K11>=5,"green",IF(K11<=3,"orange","#C9C21D"));"color2","#eeeeee"}),"Done"),"")
A12: FALSE | B12: Content decay review scheduled quarterly | C12: Flag pages with declining traffic or outdated information | E12: =IF(D12="Not Relevant","",IF(D12="Good","",IF(D12="Bad",1.33,1))) | G12: =IFERROR(SPARKLINE(F12,{"charttype","bar";"max",3;"min",1;"color1",IF(F12=3,"#4078DD",IF(F12=2,"#9CB7E9","#CED9EF"))}),"") | I12: =IFERROR(SPARKLINE(H12,{"charttype","bar";"max",3;"min",1;"color1",IF(H12=3,"#4078DD",IF(H12=2,"#9CB7E9","#CED9EF"))}),"") | J12: =IF(H12=1,3,IF(H12=2,2,1)) | K12: =ROUNDUP(((J12+F12)*E12),1) | L12: 8 | M12: =IFERROR(IF(A12=FALSE,SPARKLINE(K12:L12,{"charttype","bar";"max",8;"min",0;"color1",IF(K12>=5,"green",IF(K12<=3,"orange","#C9C21D"));"color2","#eeeeee"}),"Done"),"")
A13: FALSE | B13: Data study planned with original research | C13: Survey or analysis producing unique statistics others will cite | E13: =IF(D13="Not Relevant","",IF(D13="Good","",IF(D13="Bad",1.33,1))) | G13: =IFERROR(SPARKLINE(F13,{"charttype","bar";"max",3;"min",1;"color1",IF(F13=3,"#4078DD",IF(F13=2,"#9CB7E9","#CED9EF"))}),"") | I13: =IFERROR(SPARKLINE(H13,{"charttype","bar";"max",3;"min",1;"color1",IF(H13=3,"#4078DD",IF(H13=2,"#9CB7E9","#CED9EF"))}),"") | J13: =IF(H13=1,3,IF(H13=2,2,1)) | K13: =ROUNDUP(((J13+F13)*E13),1) | L13: 8 | M13: =IFERROR(IF(A13=FALSE,SPARKLINE(K13:L13,{"charttype","bar";"max",8;"min",0;"color1",IF(K13>=5,"green",IF(K13<=3,"orange","#C9C21D"));"color2","#eeeeee"}),"Done"),"")
A14: FALSE | B14: Integration partner pages created | C14: /integrations/slack and /integrations/zapier with setup details | E14: =IF(D14="Not Relevant","",IF(D14="Good","",IF(D14="Bad",1.33,1))) | G14: =IFERROR(SPARKLINE(F14,{"charttype","bar";"max",3;"min",1;"color1",IF(F14=3,"#4078DD",IF(F14=2,"#9CB7E9","#CED9EF"))}),"") | I14: =IFERROR(SPARKLINE(H14,{"charttype","bar";"max",3;"min",1;"color1",IF(H14=3,"#4078DD",IF(H14=2,"#9CB7E9","#CED9EF"))}),"") | J14: =IF(H14=1,3,IF(H14=2,2,1)) | K14: =ROUNDUP(((J14+F14)*E14),1) | L14: 8 | M14: =IFERROR(IF(A14=FALSE,SPARKLINE(K14:L14,{"charttype","bar";"max",8;"min",0;"color1",IF(K14>=5,"green",IF(K14<=3,"orange","#C9C21D"));"color2","#eeeeee"}),"Done"),"")

Sheet Competitive Intelligence
B1: Competitive Intelligence - AEO Checkpoint | C1: Example | D1: Evaluation | E1: Factor | F1: Impact | G1: Impact | H1: Cost | I1: Cost | J1: Cost for Sum | K1: Sum | L1: Max | M1: Priority
B2: Competitive Intelligence
A3: FALSE | B3: Top 5 competitors identified via LLM queries | C3: Ask "Best [category]" on each LLM and document which brands appear | E3: =IF(D3="Not Relevant","",IF(D3="Good","",IF(D3="Bad",1.33,1))) | G3: =IFERROR(SPARKLINE(F3,{"charttype","bar";"max",3;"min",1;"color1",IF(F3=3,"#4078DD",IF(F3=2,"#9CB7E9","#CED9EF"))}),"") | I3: =IFERROR(SPARKLINE(H3,{"charttype","bar";"max",3;"min",1;"color1",IF(H3=3,"#4078DD",IF(H3=2,"#9CB7E9","#CED9EF"))}),"") | J3: =IF(H3=1,3,IF(H3=2,2,1)) | K3: =ROUNDUP(((J3+F3)*E3),1) | L3: 8 | M3: =IFERROR(IF(A3=FALSE,SPARKLINE(K3:L3,{"charttype","bar";"max",8;"min",0;"color1",IF(K3>=5,"green",IF(K3<=3,"orange","#C9C21D"));"color2","#eeeeee"}),"Done"),"")
A4: FALSE | B4: Competitor LLM visibility audited | C4: Run same discovery queries for competitors and compare mention rates | E4: =IF(D4="Not Relevant","",IF(D4="Good","",IF(D4="Bad",1.33,1))) | G4: =IFERROR(SPARKLINE(F4,{"charttype","bar";"max",3;"min",1;"color1",IF(F4=3,"#4078DD",IF(F4=2,"#9CB7E9","#CED9EF"))}),"") | I4: =IFERROR(SPARKLINE(H4,{"charttype","bar";"max",3;"min",1;"color1",IF(H4=3,"#4078DD",IF(H4=2,"#9CB7E9","#CED9EF"))}),"") | J4: =IF(H4=1,3,IF(H4=2,2,1)) | K4: =ROUNDUP(((J4+F4)*E4),1) | L4: 8 | M4: =IFERROR(IF(A4=FALSE,SPARKLINE(K4:L4,{"charttype","bar";"max",8;"min",0;"color1",IF(K4>=5,"green",IF(K4<=3,"orange","#C9C21D"));"color2","#eeeeee"}),"Done"),"")
A5: FALSE | B5: Keyword gap analysis completed (DataForSEO or similar) | C5: Identify keywords competitors rank for that you don't | E5: =IF(D5="Not Relevant","",IF(D5="Good","",IF(D5="Bad",1.33,1))) | G5: =IFERROR(SPARKLINE(F5,{"charttype","bar";"max",3;"min",1;"color1",IF(F5=3,"#4078DD",IF(F5=2,"#9CB7E9","#CED9EF"))}),"") | I5: =IFERROR(SPARKLINE(H5,{"charttype","bar";"max",3;"min",1;"color1",IF(H5=3,"#4078DD",IF(H5=2,"#9CB7E9","#CED9EF"))}),"") | J5: =IF(H5=1,3,IF(H5=2,2,1)) | K5: =ROUNDUP(((J5+F5)*E5),1) | L5: 8 | M5: =IFERROR(IF(A5=FALSE,SPARKLINE(K5:L5,{"charttype","bar";"max",8;"min",0;"color1",IF(K5>=5,"green",IF(K5<=3,"orange","#C9C21D"));"color2","#eeeeee"}),"Done"),"")
A6: FALSE | B6: vs comparison pages created for each competitor | C6: /vs/competitor-name with honest feature and pricing comparison tables | E6: =IF(D6="Not Relevant","",IF(D6="Good","",IF(D6="Bad",1.33,1))) | G6: =IFERROR(SPARKLINE(F6,{"charttype","bar";"max",3;"min",1;"color1",IF(F6=3,"#4078DD",IF(F6=2,"#9CB7E9","#CED9EF"))}),"") | I6: =IFERROR(SPARKLINE(H6,{"charttype","bar";"max",3;"min",1;"color1",IF(H6=3,"#4078DD",IF(H6=2,"#9CB7E9","#CED9EF"))}),"") | J6: =IF(H6=1,3,IF(H6=2,2,1)) | K6: =ROUNDUP(((J6+F6)*E6),1) | L6: 8 | M6: =IFERROR(IF(A6=FALSE,SPARKLINE(K6:L6,{"charttype","bar";"max",8;"min",0;"color1",IF(K6>=5,"green",IF(K6<=3,"orange","#C9C21D"));"color2","#eeeeee"}),"Done"),"")
